Workbook

Sheet Resumen y Aprovechamiento
A1: Tabla 0. Resumen del direccionamiento y porcentaje de aprovechamiento
A2: Todas las cifras se calculan desde las hojas VLSM y FLSM. Aprovechamiento = hosts requeridos ÷ direcciones asignadas × 100.
A4: Bloque | B4: Subredes | C4: Hosts requeridos | D4: Direcciones asignadas | E4: Hosts útiles | F4: Aprovechamiento (req./asignadas) | G4: Fórmula
A5: VLSM departamental (7 subredes) | B5: =COUNT('VLSM Departamental'!D6:D12) -> 7 | C5: =SUM('VLSM Departamental'!D6:D12) -> 745 | D5: =SUM('VLSM Departamental'!G6:G12) -> 1088 | E5: =SUM('VLSM Departamental'!H6:H12) -> 1074 | F5: =IF(D5=0,"",C5/D5) -> 0.68474265 | G5: ="="&C5&" ÷ "&D5&" × 100" -> =745 ÷ 1088 × 100
A6: VLSM complementario (Wi-Fi y gestión) | B6: =COUNT('VLSM Complementario'!D6:D8) -> 3 | C6: =SUM('VLSM Complementario'!D6:D8) -> 320 | D6: =SUM('VLSM Complementario'!G6:G8) -> 416 | E6: =SUM('VLSM Complementario'!H6:H8) -> 410 | F6: =IF(D6=0,"",C6/D6) -> 0.76923077 | G6: ="="&C6&" ÷ "&D6&" × 100" -> =320 ÷ 416 × 100
A7: Subtotal VLSM | B7: =B5+B6 -> 10 | C7: =C5+C6 -> 1065 | D7: =D5+D6 -> 1504 | E7: =E5+E6 -> 1484 | F7: =IF(D7=0,"",C7/D7) -> 0.7081117 | G7: ="="&C7&" ÷ "&D7&" × 100" -> =1065 ÷ 1504 × 100
A8: FLSM /30 (6 enlaces en uso + 2 reservas) | B8: =COUNTA('FLSM Enlaces'!B6:B13) -> 8 | C8: =B11*2 -> 12 | D8: =B8*2^(32-'FLSM Enlaces'!H3) -> 32 | E8: =SUM('FLSM Enlaces'!L6:L13) -> 16 | F8: =IF(D8=0,"",C8/D8) -> 0.375 | G8: ="="&C8&" ÷ "&D8&" × 100" -> =12 ÷ 32 × 100
A9: Total diseño | B9: =B7+B8 -> 18 | C9: =C7+C8 -> 1077 | D9: =D7+D8 -> 1536 | E9: =E7+E8 -> 1500 | F9: =IF(D9=0,"",C9/D9) -> 0.70117188 | G9: ="="&C9&" ÷ "&D9&" × 100" -> =1077 ÷ 1536 × 100
A11: Enlaces /30 en uso | B11: 6 | C11: Enlaces con equipos en ambos extremos (Norte, Sur, Occidente, DSW1, DSW2, R-EDGE). Los 2 de reserva no tienen hosts.
A13: Cómo leer el aprovechamiento
A14: VLSM: cada subred usa la menor potencia de 2 que cubre hosts + 2 (red y broadcast). El sobrante de cada bloque es el «desperdicio».
A15: FLSM /30: cada enlace tiene 4 direcciones y 2 útiles, así que su techo es 50 %; con 2 bloques de reserva vacíos baja a 37.5 %.
A16: El total combina ambos: (hosts requeridos VLSM + extremos de enlaces en uso) ÷ (1,504 + 32).
A17: Hosts requeridos de Wi-Fi y gestión (200, 100 y 20) son valores de diseño del equipo, no del enunciado.
A19: Ocupación del resumen y del bloque privado
A20: Referencia | B20: Direcciones | C20: Usadas por el diseño | D20: Ocupación
A21: Resumen CIDR 172.30.0.0/21 | B21: ='CIDR Resumen'!B12 -> 2048 | C21: =D9 -> 1536 | D21: =C21/B21 -> 0.75
A22: Bloque 172.30.0.0/16 | B22: =2^16 -> 65536 | C22: =D9 -> 1536 | D22: =C22/B22 -> 0.0234375
A23: Siguiente dirección libre | B23: ="172.30.4.96" -> 172.30.4.96 | C23: Tras la última reserva FLSM 172.30.4.92/30. 172.30.0.0/24 reservada (no asignable) por el resumen.

Sheet Capacidad Wi-Fi
A1: Tabla 7. Capacidad de las redes inalámbricas tras reservas
A2: Celdas azules = datos de entrada. Celdas amarillas = rangos de pools de SRV-DHCP y SRV-DHCP-2 en v6 (fuente: entrega2/revision/04-resultados-pruebas-v6.md).
A4: Concepto | B4: Wi-Fi Corporativo (VLAN 50) | C4: Wi-Fi Invitados (VLAN 60) | D4: Nota
A5: Red | B5: 172.30.6.0/25 | C5: 172.30.5.0/24
A6: Bits de host | B6: ='VLSM Complementario'!E7 -> 7 | C6: ='VLSM Complementario'!E6 -> 8
A7: Hosts útiles (2^h − 2) | B7: ='VLSM Complementario'!H7 -> 126 | C7: ='VLSM Complementario'!H6 -> 254
A8: Reserva: gateway | B8: 1 | C8: 1 | D8: Corp: IP virtual HSRP .1. Invitados: R-EDGE Gi0/2 .1
A9: Reserva: interfaces de distribución | B9: 2 | C9: 0 | D9: Corp: SVI DSW1 .2 y DSW2 .3. Invitados: sin SVI 60 desde v5
A10: Reserva: infraestructura (APs, estáticas) | B10: 7 | C10: 9 | D10: Bloque .1–.10 excluido de los pools en ambos casos
A11: Capacidad para clientes tras reservas | B11: =B7-B8-B9-B10 -> 116 | C11: =C7-C8-C9-C10 -> 244
A12: Pool primario SRV-DHCP: primera IP (último octeto) | B12: 11 | C12: 11 | D12: v6, revision/03 y 04
A13: Pool primario SRV-DHCP: última IP | B13: 85 | C13: 180 | D13: v6: corp inicio .11 y 75 usuarios; invitados .11 y 170
A14: Pool secundario SRV-DHCP-2: primera IP | B14: 86 | C14: 181 | D14: v6, revision/03 y 04
A15: Pool secundario SRV-DHCP-2: última IP | B15: 120 | C15: 250 | D15: v6: corp 35 usuarios; invitados 70
A16: Direcciones entregables por los dos pools | B16: =IF(COUNT(B12:B15)<4,"pendiente",(B13-B12+1)+(B15-B14+1)) -> 110 | C16: =IF(COUNT(C12:C15)<4,"pendiente",(C13-C12+1)+(C15-C14+1)) -> 240 | D16: Suma de los dos tramos
A17: Traslape entre pools | B17: =IF(COUNT(B12:B15)<4,"pendiente",IF(B14>B13,"No","Sí, corregir")) -> No | C17: =IF(COUNT(C12:C15)<4,"pendiente",IF(C14>C13,"No","Sí, corregir")) -> No
A18: Pools dentro de la capacidad | B18: =IF(COUNT(B12:B15)<4,"pendiente",IF(AND(B12>B10+B8+B9,B15<=B7),"Sí","No")) -> Sí | C18: =IF(COUNT(C12:C15)<4,"pendiente",IF(AND(C12>C10+C8+C9,C15<=C7),"Sí","No")) -> Sí | D18: Inicio después de las reservas y fin antes del broadcast
A19: Demanda de diseño (clientes simultáneos) | B19: ='VLSM Complementario'!D7 -> 100 | C19: ='VLSM Complementario'!D6 -> 200 | D19: Valor de diseño de la hoja VLSM Complementario
A20: Ocupación con la demanda de diseño | B20: =B19/B11 -> 0.86206897 | C20: =C19/C11 -> 0.81967213
A21: Margen libre (clientes adicionales) | B21: =B11-B19 -> 16 | C21: =C11-C19 -> 44
A22: Clientes inalámbricos en la simulación | B22: 1 | C22: 1 | D22: LAP-CORP y LAP-INVITADO
A24: Lectura: la capacidad tras reservas es el techo de clientes; los pools pueden entregar menos si se dejan direcciones libres. Packet Tracer limita cada pool a un solo DNS.

Sheet Crecimiento 3 años
A1: Tabla 8. Plan de crecimiento a tres años (2,400 dispositivos nuevos)
A2: Reparto proporcional a los usuarios actuales de cada sede/departamento. Celdas azules = supuestos editables. Bloque público 200.100.50.0/24 sin cambios.
A3: Dispositivos nuevos a 3 años | D3: 2400
A4: Fase por año (% del total) | B4: Año 1 | C4: Año 2 | D4: Año 3
B5: 0.25 | C5: 0.33 | D5: =1-B5-C5 -> 0.42 | E5: Supuesto: crecimiento acelerado (25 %, 33 %, 42 %). El enunciado no fija el ritmo.
A7: # | B7: Sede / departamento | C7: Sede | D7: Usuarios actuales | E7: Participación | F7: Nuevos (3 años) | G7: Acumulado año 1 | H7: Acumulado año 2 | I7: Acumulado año 3 | J7: Total al año 3 | K7: Hosts subred de crecimiento | L7: Bits de host (h) | M7: Prefijo | N7: Tamaño de bloque | O7: Desplazamiento | P7: Dirección de red | Q7: Rango útil | R7: Broadcast | S7: Máscara | T7: Alineación | U7: Aprovechamiento
A8: 1 | B8: Centro de Ingeniería | C8: Sede Central | D8: ='VLSM Departamental'!D6 -> 210 | E8: =D8/$D$15 -> 0.28187919 | F8: =ROUND($D$3*E8,0) -> 677 | G8: =ROUND(F8*$B$5,0) -> 169 | H8: =ROUND(F8*($B$5+$C$5),0) -> 393 | I8: =F8 -> 677 | J8: =D8+I8 -> 887 | K8: =F8 -> 677 | L8: =CEILING(LOG(K8+2,2),1) -> 10 | M8: ="/"&(32-L8) -> /22 | N8: =2^L8 -> 1024 | O8: 2048 | P8: ="172.30."&INT(O8/256)&"."&MOD(O8,256) -> 172.30.8.0 | Q8: ="172.30."&INT((O8+1)/256)&"."&MOD((O8+1),256)&" – "&"172.30."&INT((O8+N8-2)/256)&"."&MOD((O8+N8-2),256) -> 172.30.8.1 – 172.30.11.254 | R8: ="172.30."&INT((O8+N8-1)/256)&"."&MOD((O8+N8-1),256) -> 172.30.11.255 | S8: =IF(L8<=8,"255.255.255."&(256-N8),"255.255."&(256-N8/256)&".0") -> 255.255.252.0 | T8: =IF(MOD(O8,N8)=0,"Alineado","Revisar") -> Alineado | U8: =K8/N8 -> 0.66113281
A9: 2 | B9: Sucursal Norte | C9: Norte | D9: ='VLSM Departamental'!D7 -> 140 | E9: =D9/$D$15 -> 0.18791946 | F9: =ROUND($D$3*E9,0) -> 451 | G9: =ROUND(F9*$B$5,0) -> 113 | H9: =ROUND(F9*($B$5+$C$5),0) -> 262 | I9: =F9 -> 451 | J9: =D9+I9 -> 591 | K9: =F9 -> 451 | L9: =CEILING(LOG(K9+2,2),1) -> 9 | M9: ="/"&(32-L9) -> /23 | N9: =2^L9 -> 512 | O9: 4096 | P9: ="172.30."&INT(O9/256)&"."&MOD(O9,256) -> 172.30.16.0 | Q9: ="172.30."&INT((O9+1)/256)&"."&MOD((O9+1),256)&" – "&"172.30."&INT((O9+N9-2)/256)&"."&MOD((O9+N9-2),256) -> 172.30.16.1 – 172.30.17.254 | R9: ="172.30."&INT((O9+N9-1)/256)&"."&MOD((O9+N9-1),256) -> 172.30.17.255 | S9: =IF(L9<=8,"255.255.255."&(256-N9),"255.255."&(256-N9/256)&".0") -> 255.255.254.0 | T9: =IF(MOD(O9,N9)=0,"Alineado","Revisar") -> Alineado | U9: =K9/N9 -> 0.88085938
A10: 3 | B10: Edificio Administrativo | C10: Sede Central | D10: ='VLSM Departamental'!D8 -> 120 | E10: =D10/$D$15 -> 0.16107383 | F10: =ROUND($D$3*E10,0) -> 387 | G10: =ROUND(F10*$B$5,0) -> 97 | H10: =ROUND(F10*($B$5+$C$5),0) -> 224 | I10: =F10 -> 387 | J10: =D10+I10 -> 507 | K10: =F10 -> 387 | L10: =CEILING(LOG(K10+2,2),1) -> 9 | M10: ="/"&(32-L10) -> /23 | N10: =2^L10 -> 512 | O10: 3072 | P10: ="172.30."&INT(O10/256)&"."&MOD(O10,256) -> 172.30.12.0 | Q10: ="172.30."&INT((O10+1)/256)&"."&MOD((O10+1),256)&" – "&"172.30."&INT((O10+N10-2)/256)&"."&MOD((O10+N10-2),256) -> 172.30.12.1 – 172.30.13.254 | R10: ="172.30."&INT((O10+N10-1)/256)&"."&MOD((O10+N10-1),256) -> 172.30.13.255 | S10: =IF(L10<=8,"255.255.255."&(256-N10),"255.255."&(256-N10/256)&".0") -> 255.255.254.0 | T10: =IF(MOD(O10,N10)=0,"Alineado","Revisar") -> Alineado | U10: =K10/N10 -> 0.75585938
A11: 4 | B11: Sucursal Sur | C11: Sur | D11: ='VLSM Departamental'!D9 -> 95 | E11: =D11/$D$15 -> 0.12751678 | F11: =ROUND($D$3*E11,0) -> 306 | G11: =ROUND(F11*$B$5,0) -> 77 | H11: =ROUND(F11*($B$5+$C$5),0) -> 177 | I11: =F11 -> 306 | J11: =D11+I11 -> 401 | K11: =F11 -> 306 | L11: =CEILING(LOG(K11+2,2),1) -> 9 | M11: ="/"&(32-L11) -> /23 | N11: =2^L11 -> 512 | O11: 5120 | P11: ="172.30."&INT(O11/256)&"."&MOD(O11,256) -> 172.30.20.0 | Q11: ="172.30."&INT((O11+1)/256)&"."&MOD((O11+1),256)&" – "&"172.30."&INT((O11+N11-2)/256)&"."&MOD((O11+N11-2),256) -> 172.30.20.1 – 172.30.21.254 | R11: ="172.30."&INT((O11+N11-1)/256)&"."&MOD((O11+N11-1),256) -> 172.30.21.255 | S11: =IF(L11<=8,"255.255.255."&(256-N11),"255.255."&(256-N11/256)&".0") -> 255.255.254.0 | T11: =IF(MOD(O11,N11)=0,"Alineado","Revisar") -> Alineado | U11: =K11/N11 -> 0.59765625
A12: 5 | B12: Sucursal Occidente | C12: Occidente | D12: ='VLSM Departamental'!D10 -> 80 | E12: =D12/$D$15 -> 0.10738255 | F12: =ROUND($D$3*E12,0) -> 258 | G12: =ROUND(F12*$B$5,0) -> 65 | H12: =ROUND(F12*($B$5+$C$5),0) -> 150 | I12: =F12 -> 258 | J12: =D12+I12 -> 338 | K12: =F12 -> 258 | L12: =CEILING(LOG(K12+2,2),1) -> 9 | M12: ="/"&(32-L12) -> /23 | N12: =2^L12 -> 512 | O12: 6144 | P12: ="172.30."&INT(O12/256)&"."&MOD(O12,256) -> 172.30.24.0 | Q12: ="172.30."&INT((O12+1)/256)&"."&MOD((O12+1),256)&" – "&"172.30."&INT((O12+N12-2)/256)&"."&MOD((O12+N12-2),256) -> 172.30.24.1 – 172.30.25.254 | R12: ="172.30."&INT((O12+N12-1)/256)&"."&MOD((O12+N12-1),256) -> 172.30.25.255 | S12: =IF(L12<=8,"255.255.255."&(256-N12),"255.255."&(256-N12/256)&".0") -> 255.255.254.0 | T12: =IF(MOD(O12,N12)=0,"Alineado","Revisar") -> Alineado | U12: =K12/N12 -> 0.50390625
A13: 6 | B13: Área Financiera | C13: Sede Central | D13: ='VLSM Departamental'!D11 -> 65 | E13: =D13/$D$15 -> 0.087248322 | F13: =ROUND($D$3*E13,0) -> 209 | G13: =ROUND(F13*$B$5,0) -> 52 | H13: =ROUND(F13*($B$5+$C$5),0) -> 121 | I13: =F13 -> 209 | J13: =D13+I13 -> 274 | K13: =F13 -> 209 | L13: =CEILING(LOG(K13+2,2),1) -> 8 | M13: ="/"&(32-L13) -> /24 | N13: =2^L13 -> 256 | O13: 3584 | P13: ="172.30."&INT(O13/256)&"."&MOD(O13,256) -> 172.30.14.0 | Q13: ="172.30."&INT((O13+1)/256)&"."&MOD((O13+1),256)&" – "&"172.30."&INT((O13+N13-2)/256)&"."&MOD((O13+N13-2),256) -> 172.30.14.1 – 172.30.14.254 | R13: ="172.30."&INT((O13+N13-1)/256)&"."&MOD((O13+N13-1),256) -> 172.30.14.255 | S13: =IF(L13<=8,"255.255.255."&(256-N13),"255.255."&(256-N13/256)&".0") -> 255.255.255.0 | T13: =IF(MOD(O13,N13)=0,"Alineado","Revisar") -> Alineado | U13: =K13/N13 -> 0.81640625
A14: 7 | B14: Data Center (servidores virtuales) | C14: Sede Central | D14: ='VLSM Departamental'!D12 -> 35 | E14: =D14/$D$15 -> 0.046979866 | F14: =$D$3-SUM(F8:F13) -> 112 | G14: =ROUND(F14*$B$5,0) -> 28 | H14: =ROUND(F14*($B$5+$C$5),0) -> 65 | I14: =F14 -> 112 | J14: =D14+I14 -> 147 | K14: =F14 -> 112 | L14: =CEILING(LOG(K14+2,2),1) -> 7 | M14: ="/"&(32-L14) -> /25 | N14: =2^L14 -> 128 | O14: 3840 | P14: ="172.30."&INT(O14/256)&"."&MOD(O14,256) -> 172.30.15.0 | Q14: ="172.30."&INT((O14+1)/256)&"."&MOD((O14+1),256)&" – "&"172.30."&INT((O14+N14-2)/256)&"."&MOD((O14+N14-2),256) -> 172.30.15.1 – 172.30.15.126 | R14: ="172.30."&INT((O14+N14-1)/256)&"."&MOD((O14+N14-1),256) -> 172.30.15.127 | S14: =IF(L14<=8,"255.255.255."&(256-N14),"255.255."&(256-N14/256)&".0") -> 255.255.255.128 | T14: =IF(MOD(O14,N14)=0,"Alineado","Revisar") -> Alineado | U14: =K14/N14 -> 0.875
B15: Total | D15: =SUM(D8:D14) -> 745 | E15: =SUM(E8:E14) -> 1 | F15: =SUM(F8:F14) -> 2400 | G15: =SUM(G8:G14) -> 601 | H15: =SUM(H8:H14) -> 1392 | I15: =SUM(I8:I14) -> 2400 | J15: =SUM(J8:J14) -> 3145 | K15: =SUM(K8:K14) -> 2400 | N15: =SUM(N8:N14) -> 3456 | U15: =K15/N15 -> 0.69444444
A16: Cada sede recibe una subred nueva para su crecimiento (no se renumeran las actuales). Los dispositivos nuevos mezclan estaciones, IoT, móviles y servidores virtuales; el equipo puede dividir cada subred en VLANs por tipo sin salir del bloque.
A18: Bloques reservados por sede (sumarizables)
A19: Sede | B19: Bloque reservado | C19: Desplazamiento | D19: Tamaño | E19: Asignado a crecimiento | F19: Libre en el bloque | G19: Uso del bloque
A20: Sede Central (ING, ADM, FIN, DC) | B20: 172.30.8.0/21 | C20: 2048 | D20: 2048 | E20: =N8+N10+N13+N14 -> 1920 | F20: =D20-E20 -> 128 | G20: =E20/D20 -> 0.9375
A21: Norte | B21: 172.30.16.0/22 | C21: 4096 | D21: 1024 | E21: =N9 -> 512 | F21: =D21-E21 -> 512 | G21: =E21/D21 -> 0.5
A22: Sur | B22: 172.30.20.0/22 | C22: 5120 | D22: 1024 | E22: =N11 -> 512 | F22: =D22-E22 -> 512 | G22: =E22/D22 -> 0.5
A23: Occidente | B23: 172.30.24.0/22 | C23: 6144 | D23: 1024 | E23: =N12 -> 512 | F23: =D23-E23 -> 512 | G23: =E23/D23 -> 0.5
A24: Reserva (nuevos enlaces, nueva sede, VLAN IoT) | B24: 172.30.28.0/22 | C24: 7168 | D24: 1024 | E24: 0 | F24: =D24-E24 -> 1024 | G24: =E24/D24 -> 0
A25: Total crecimiento | D25: =SUM(D20:D24) -> 6144 | E25: =SUM(E20:E24) -> 3456 | F25: =SUM(F20:F24) -> 2688 | G25: =E25/D25 -> 0.5625
A27: Resumen CIDR al año 3
A28: Concepto | B28: Valor
A29: Diseño actual (resumen /21) | B29: ='CIDR Resumen'!B12 -> 2048
A30: Bloques de crecimiento | B30: =D25 -> 6144
A31: Espacio total ocupado o reservado | B31: =B29+B30 -> 8192
A32: Prefijo del nuevo resumen | B32: ="/"&(16+(16-CEILING(LOG(B31,2),1))) -> /19
A33: Nuevo resumen | B33: ="172.30.0.0"&B32 -> 172.30.0.0/19
A34: Direcciones del nuevo resumen | B34: =2^CEILING(LOG(B31,2),1) -> 8192
A35: Wildcard de ACL 1 (NAT) | B35: ="0.0."&(B34/256-1)&".255" -> 0.0.31.255
A36: Ocupación del /16 al año 3 | B36: =B34/2^16 -> 0.125
A38: Al año 3 R-CORE cambia «area 0 range» a 172.30.0.0 255.255.224.0 y R-EDGE su estática flotante. Cada bloque de sucursal se puede resumir aparte (por ejemplo 172.30.16.0/22 hacia Norte).
A40: Bloque público 200.100.50.0/24 (fijo)
A41: Subred | B41: Prefijo | C41: Direcciones | D41: Uso | E41: Estado
A42: 200.100.50.0 | B42: /30 | C42: =2^(32-VALUE(MID(B42,2,2))) -> 4 | D42: R-EDGE Gi0/1 .2 ↔ R-ISP .1 | E42: En uso
A43: 200.100.50.4 | B43: /30 | C43: =2^(32-VALUE(MID(B43,2,2))) -> 4 | D43: Segundo enlace a otro ISP (redundancia) | E43: Reserva
A44: 200.100.50.8 | B44: /29 | C44: =2^(32-VALUE(MID(B44,2,2))) -> 8 | D44: Servidores publicados por NAT estático (web 200.100.50.10) | E44: En uso parcial
A45: 200.100.50.16 | B45: /28 | C45: =2^(32-VALUE(MID(B45,2,2))) -> 16 | D45: Pool PAT adicional si 200.100.50.2 se satura | E45: Reserva
...

Sheet Pools DHCP
A1: Tabla 10. Ámbitos DHCP de la versión final y verificación
A2: Fuente: entrega2/revision/03 y 04 (v6) con Ingeniería en 172.30.7.0/24. Split-scope: SRV-DHCP 172.30.4.11 (DNS .10) y SRV-DHCP-2 172.30.4.16 (DNS .17).
A4: Ámbito | B4: Red (3 primeros octetos) | C4: Último octeto de red | D4: Hosts útiles de la subred | E4: Hosts requeridos | F4: Inicio primario | G4: Máx. primario | H4: Fin primario | I4: Inicio secundario | J4: Máx. secundario | K4: Fin secundario | L4: Total entregable | M4: Cubre requisito | N4: Sin traslape | O4: Dentro de la subred | P4: Reservadas antes del pool
A5: ING | B5: 172.30.7 | C5: 0 | D5: ='VLSM Departamental'!H6 -> 254 | E5: ='VLSM Departamental'!D6 -> 210 | F5: 11 | G5: 170 | H5: =F5+G5-1 -> 180 | I5: 181 | J5: 70 | K5: =I5+J5-1 -> 250 | L5: =G5+J5 -> 240 | M5: =IF(L5>=E5,"Sí","No") -> Sí | N5: =IF(I5>H5,"Sí","No") -> Sí | O5: =IF(AND(F5>C5,K5<=C5+D5),"Sí","No") -> Sí | P5: =F5-C5-1 -> 10
A6: ADM | B6: 172.30.2 | C6: 0 | D6: ='VLSM Departamental'!H8 -> 126 | E6: ='VLSM Departamental'!D8 -> 120 | F6: 4 | G6: 86 | H6: =F6+G6-1 -> 89 | I6: 90 | J6: 37 | K6: =I6+J6-1 -> 126 | L6: =G6+J6 -> 123 | M6: =IF(L6>=E6,"Sí","No") -> Sí | N6: =IF(I6>H6,"Sí","No") -> Sí | O6: =IF(AND(F6>C6,K6<=C6+D6),"Sí","No") -> Sí | P6: =F6-C6-1 -> 3
A7: FIN | B7: 172.30.3 | C7: 128 | D7: ='VLSM Departamental'!H11 -> 126 | E7: ='VLSM Departamental'!D11 -> 65 | F7: 139 | G7: 77 | H7: =F7+G7-1 -> 215 | I7: 216 | J7: 33 | K7: =I7+J7-1 -> 248 | L7: =G7+J7 -> 110 | M7: =IF(L7>=E7,"Sí","No") -> Sí | N7: =IF(I7>H7,"Sí","No") -> Sí | O7: =IF(AND(F7>C7,K7<=C7+D7),"Sí","No") -> Sí | P7: =F7-C7-1 -> 10
A8: NORTE | B8: 172.30.1 | C8: 0 | D8: ='VLSM Departamental'!H7 -> 254 | E8: ='VLSM Departamental'!D7 -> 140 | F8: 11 | G8: 170 | H8: =F8+G8-1 -> 180 | I8: 181 | J8: 70 | K8: =I8+J8-1 -> 250 | L8: =G8+J8 -> 240 | M8: =IF(L8>=E8,"Sí","No") -> Sí | N8: =IF(I8>H8,"Sí","No") -> Sí | O8: =IF(AND(F8>C8,K8<=C8+D8),"Sí","No") -> Sí | P8: =F8-C8-1 -> 10
A9: SUR | B9: 172.30.2 | C9: 128 | D9: ='VLSM Departamental'!H9 -> 126 | E9: ='VLSM Departamental'!D9 -> 95 | F9: 139 | G9: 77 | H9: =F9+G9-1 -> 215 | I9: 216 | J9: 33 | K9: =I9+J9-1 -> 248 | L9: =G9+J9 -> 110 | M9: =IF(L9>=E9,"Sí","No") -> Sí | N9: =IF(I9>H9,"Sí","No") -> Sí | O9: =IF(AND(F9>C9,K9<=C9+D9),"Sí","No") -> Sí | P9: =F9-C9-1 -> 10
A10: OCC | B10: 172.30.3 | C10: 0 | D10: ='VLSM Departamental'!H10 -> 126 | E10: ='VLSM Departamental'!D10 -> 80 | F10: 11 | G10: 77 | H10: =F10+G10-1 -> 87 | I10: 88 | J10: 33 | K10: =I10+J10-1 -> 120 | L10: =G10+J10 -> 110 | M10: =IF(L10>=E10,"Sí","No") -> Sí | N10: =IF(I10>H10,"Sí","No") -> Sí | O10: =IF(AND(F10>C10,K10<=C10+D10),"Sí","No") -> Sí | P10: =F10-C10-1 -> 10
A11: WIFI-CORP | B11: 172.30.6 | C11: 0 | D11: ='VLSM Complementario'!H7 -> 126 | E11: ='VLSM Complementario'!D7 -> 100 | F11: 11 | G11: 75 | H11: =F11+G11-1 -> 85 | I11: 86 | J11: 35 | K11: =I11+J11-1 -> 120 | L11: =G11+J11 -> 110 | M11: =IF(L11>=E11,"Sí","No") -> Sí | N11: =IF(I11>H11,"Sí","No") -> Sí | O11: =IF(AND(F11>C11,K11<=C11+D11),"Sí","No") -> Sí | P11: =F11-C11-1 -> 10
A12: WIFI-INV | B12: 172.30.5 | C12: 0 | D12: ='VLSM Complementario'!H6 -> 254 | E12: ='VLSM Complementario'!D6 -> 200 | F12: 11 | G12: 170 | H12: =F12+G12-1 -> 180 | I12: 181 | J12: 70 | K12: =I12+J12-1 -> 250 | L12: =G12+J12 -> 240 | M12: =IF(L12>=E12,"Sí","No") -> Sí | N12: =IF(I12>H12,"Sí","No") -> Sí | O12: =IF(AND(F12>C12,K12<=C12+D12),"Sí","No") -> Sí | P12: =F12-C12-1 -> 10
A13: Total | E13: =SUM(E5:E12) -> 1010 | L13: =SUM(L5:L12) -> 1283 | M13: =IF(COUNTIF(M5:M12,"Sí")=8,"8/8 cumplen","Revisar") -> 8/8 cumplen | N13: =IF(COUNTIF(N5:N12,"Sí")=8,"8/8","Revisar") -> 8/8 | O13: =IF(COUNTIF(O5:O12,"Sí")=8,"8/8","Revisar") -> 8/8
A15: Los octetos son el último octeto de la IP; Fin = inicio + máximo − 1. Wi-Fi: la demanda es el valor de diseño.
A16: serverPool por defecto de PT: 172.30.4.62 (primario) y 172.30.4.61 (secundario), una dirección cada uno, fuera de las IP usadas en VLAN 40 (.1–.3, .10–.17).
A17: Respaldo parcial: si cae el primario, el secundario solo entrega su tramo (≈30 %) y con DNS .17; PT admite un solo DNS por pool.
A18: Matriz IP verificada contra entrega2/revision/configs_final (v6); la versión final solo cambia Vlan10 de DSW1/DSW2 (.7.2/.7.3), POOL-ING/ING-B y ACL-GESTION (172.30.7.0/24).

Sheet VLSM Departamental
A1: Tabla 1. Plan VLSM departamental de la red 172.30.0.0/16
A2: Nexus Corporation. Orden de mayor a menor según hosts requeridos. Versión final: Ingeniería se reubica en 172.30.7.0/24 y 172.30.0.0/24 queda reservada (no asignable) para que el resumen 172.30.0.0/21 no comparta Link State ID con una subred.
A3: Desplazamiento inicial (direcciones desde 172.30.0.0): | H3: 0
A5: # | B5: Subred / Segmento | C5: VLAN | D5: Hosts requeridos | E5: Bits de host (h) | F5: Prefijo CIDR | G5: Tamaño de bloque (2^h) | H5: Hosts útiles (2^h − 2) | I5: Desperdicio | J5: Desplazamiento | K5: Dirección de red | L5: Primera IP útil | M5: Última IP útil | N5: Broadcast | O5: Máscara decimal | P5: Puerta de enlace
A6: 1 | B6: Centro de Ingeniería (Sede Central) | C6: 10 | D6: 210 | E6: =CEILING(LOG(D6+2,2),1) -> 8 | F6: ="/"&(32-E6) -> /24 | G6: =2^E6 -> 256 | H6: =G6-2 -> 254 | I6: =H6-D6 -> 44 | J6: 1792 | K6: ="172.30."&INT(J6/256)&"."&MOD(J6,256) -> 172.30.7.0 | L6: ="172.30."&INT((J6+1)/256)&"."&MOD((J6+1),256) -> 172.30.7.1 | M6: ="172.30."&INT((J6+G6-2)/256)&"."&MOD((J6+G6-2),256) -> 172.30.7.254 | N6: ="172.30."&INT((J6+G6-1)/256)&"."&MOD((J6+G6-1),256) -> 172.30.7.255 | O6: =IF(E6<=8,"255.255.255."&(256-G6),"255.255."&(256-G6/256)&".0") -> 255.255.255.0 | P6: =L6 -> 172.30.7.1
A7: 2 | B7: Sucursal Regional Norte | C7: — | D7: 140 | E7: =CEILING(LOG(D7+2,2),1) -> 8 | F7: ="/"&(32-E7) -> /24 | G7: =2^E7 -> 256 | H7: =G7-2 -> 254 | I7: =H7-D7 -> 114 | J7: 256 | K7: ="172.30."&INT(J7/256)&"."&MOD(J7,256) -> 172.30.1.0 | L7: ="172.30."&INT((J7+1)/256)&"."&MOD((J7+1),256) -> 172.30.1.1 | M7: ="172.30."&INT((J7+G7-2)/256)&"."&MOD((J7+G7-2),256) -> 172.30.1.254 | N7: ="172.30."&INT((J7+G7-1)/256)&"."&MOD((J7+G7-1),256) -> 172.30.1.255 | O7: =IF(E7<=8,"255.255.255."&(256-G7),"255.255."&(256-G7/256)&".0") -> 255.255.255.0 | P7: =L7 -> 172.30.1.1
A8: 3 | B8: Edificio Administrativo (Sede Central) | C8: 20 | D8: 120 | E8: =CEILING(LOG(D8+2,2),1) -> 7 | F8: ="/"&(32-E8) -> /25 | G8: =2^E8 -> 128 | H8: =G8-2 -> 126 | I8: =H8-D8 -> 6 | J8: =J7+G7 -> 512 | K8: ="172.30."&INT(J8/256)&"."&MOD(J8,256) -> 172.30.2.0 | L8: ="172.30."&INT((J8+1)/256)&"."&MOD((J8+1),256) -> 172.30.2.1 | M8: ="172.30."&INT((J8+G8-2)/256)&"."&MOD((J8+G8-2),256) -> 172.30.2.126 | N8: ="172.30."&INT((J8+G8-1)/256)&"."&MOD((J8+G8-1),256) -> 172.30.2.127 | O8: =IF(E8<=8,"255.255.255."&(256-G8),"255.255."&(256-G8/256)&".0") -> 255.255.255.128 | P8: =L8 -> 172.30.2.1
A9: 4 | B9: Sucursal Regional Sur | C9: — | D9: 95 | E9: =CEILING(LOG(D9+2,2),1) -> 7 | F9: ="/"&(32-E9) -> /25 | G9: =2^E9 -> 128 | H9: =G9-2 -> 126 | I9: =H9-D9 -> 31 | J9: =J8+G8 -> 640 | K9: ="172.30."&INT(J9/256)&"."&MOD(J9,256) -> 172.30.2.128 | L9: ="172.30."&INT((J9+1)/256)&"."&MOD((J9+1),256) -> 172.30.2.129 | M9: ="172.30."&INT((J9+G9-2)/256)&"."&MOD((J9+G9-2),256) -> 172.30.2.254 | N9: ="172.30."&INT((J9+G9-1)/256)&"."&MOD((J9+G9-1),256) -> 172.30.2.255 | O9: =IF(E9<=8,"255.255.255."&(256-G9),"255.255."&(256-G9/256)&".0") -> 255.255.255.128 | P9: =L9 -> 172.30.2.129
A10: 5 | B10: Sucursal Regional Occidente | C10: — | D10: 80 | E10: =CEILING(LOG(D10+2,2),1) -> 7 | F10: ="/"&(32-E10) -> /25 | G10: =2^E10 -> 128 | H10: =G10-2 -> 126 | I10: =H10-D10 -> 46 | J10: =J9+G9 -> 768 | K10: ="172.30."&INT(J10/256)&"."&MOD(J10,256) -> 172.30.3.0 | L10: ="172.30."&INT((J10+1)/256)&"."&MOD((J10+1),256) -> 172.30.3.1 | M10: ="172.30."&INT((J10+G10-2)/256)&"."&MOD((J10+G10-2),256) -> 172.30.3.126 | N10: ="172.30."&INT((J10+G10-1)/256)&"."&MOD((J10+G10-1),256) -> 172.30.3.127 | O10: =IF(E10<=8,"255.255.255."&(256-G10),"255.255."&(256-G10/256)&".0") -> 255.255.255.128 | P10: =L10 -> 172.30.3.1
A11: 6 | B11: Área Financiera (Sede Central) | C11: 30 | D11: 65 | E11: =CEILING(LOG(D11+2,2),1) -> 7 | F11: ="/"&(32-E11) -> /25 | G11: =2^E11 -> 128 | H11: =G11-2 -> 126 | I11: =H11-D11 -> 61 | J11: =J10+G10 -> 896 | K11: ="172.30."&INT(J11/256)&"."&MOD(J11,256) -> 172.30.3.128 | L11: ="172.30."&INT((J11+1)/256)&"."&MOD((J11+1),256) -> 172.30.3.129 | M11: ="172.30."&INT((J11+G11-2)/256)&"."&MOD((J11+G11-2),256) -> 172.30.3.254 | N11: ="172.30."&INT((J11+G11-1)/256)&"."&MOD((J11+G11-1),256) -> 172.30.3.255 | O11: =IF(E11<=8,"255.255.255."&(256-G11),"255.255."&(256-G11/256)&".0") -> 255.255.255.128 | P11: =L11 -> 172.30.3.129
A12: 7 | B12: Data Center (Sede Central) | C12: 40 | D12: 35 | E12: =CEILING(LOG(D12+2,2),1) -> 6 | F12: ="/"&(32-E12) -> /26 | G12: =2^E12 -> 64 | H12: =G12-2 -> 62 | I12: =H12-D12 -> 27 | J12: =J11+G11 -> 1024 | K12: ="172.30."&INT(J12/256)&"."&MOD(J12,256) -> 172.30.4.0 | L12: ="172.30."&INT((J12+1)/256)&"."&MOD((J12+1),256) -> 172.30.4.1 | M12: ="172.30."&INT((J12+G12-2)/256)&"."&MOD((J12+G12-2),256) -> 172.30.4.62 | N12: ="172.30."&INT((J12+G12-1)/256)&"."&MOD((J12+G12-1),256) -> 172.30.4.63 | O12: =IF(E12<=8,"255.255.255."&(256-G12),"255.255."&(256-G12/256)&".0") -> 255.255.255.192 | P12: =L12 -> 172.30.4.1
B14: Total hosts requeridos | D14: =SUM(D6:D12) -> 745
B15: Total direcciones asignadas | D15: =SUM(G6:G12) -> 1088
B16: Eficiencia (hosts req. / direcciones) | D16: =D14/D15 -> 0.68474265
B17: Siguiente dirección libre | D17: ="172.30."&INT((J12+G12)/256)&"."&MOD((J12+G12),256)&" (y 172.30.0.0/24 reservada)" -> 172.30.4.64 (y 172.30.0.0/24 reservada)
B18: Reserva no asignable | D18: 172.30.0.0/24
B19: Fórmula: h = mínimo entero tal que 2^h − 2 ≥ hosts requeridos; prefijo = 32 − h. Celdas en azul = datos de entrada del caso.

Sheet VLSM Complementario
A1: Tabla 2. Subredes complementarias de infraestructura (VLSM)
A2: Segmentos de diseño añadidos para Wi-Fi y gestión. Cantidades de hosts definidas por el equipo de diseño.
A3: Desplazamiento inicial (direcciones desde 172.30.0.0): | H3: 1280
A5: # | B5: Subred / Segmento | C5: VLAN | D5: Hosts requeridos | E5: Bits de host (h) | F5: Prefijo CIDR | G5: Tamaño de bloque (2^h) | H5: Hosts útiles (2^h − 2) | I5: Desperdicio | J5: Desplazamiento | K5: Dirección de red | L5: Primera IP útil | M5: Última IP útil | N5: Broadcast | O5: Máscara decimal | P5: Puerta de enlace
A6: 1 | B6: Wi-Fi Invitados (Sede Central, portal cautivo) | C6: 60 | D6: 200 | E6: =CEILING(LOG(D6+2,2),1) -> 8 | F6: ="/"&(32-E6) -> /24 | G6: =2^E6 -> 256 | H6: =G6-2 -> 254 | I6: =H6-D6 -> 54 | J6: =$H$3 -> 1280 | K6: ="172.30."&INT(J6/256)&"."&MOD(J6,256) -> 172.30.5.0 | L6: ="172.30."&INT((J6+1)/256)&"."&MOD((J6+1),256) -> 172.30.5.1 | M6: ="172.30."&INT((J6+G6-2)/256)&"."&MOD((J6+G6-2),256) -> 172.30.5.254 | N6: ="172.30."&INT((J6+G6-1)/256)&"."&MOD((J6+G6-1),256) -> 172.30.5.255 | O6: =IF(E6<=8,"255.255.255."&(256-G6),"255.255."&(256-G6/256)&".0") -> 255.255.255.0 | P6: =L6 -> 172.30.5.1
A7: 2 | B7: Wi-Fi Corporativo (Sede Central) | C7: 50 | D7: 100 | E7: =CEILING(LOG(D7+2,2),1) -> 7 | F7: ="/"&(32-E7) -> /25 | G7: =2^E7 -> 128 | H7: =G7-2 -> 126 | I7: =H7-D7 -> 26 | J7: =J6+G6 -> 1536 | K7: ="172.30."&INT(J7/256)&"."&MOD(J7,256) -> 172.30.6.0 | L7: ="172.30."&INT((J7+1)/256)&"."&MOD((J7+1),256) -> 172.30.6.1 | M7: ="172.30."&INT((J7+G7-2)/256)&"."&MOD((J7+G7-2),256) -> 172.30.6.126 | N7: ="172.30."&INT((J7+G7-1)/256)&"."&MOD((J7+G7-1),256) -> 172.30.6.127 | O7: =IF(E7<=8,"255.255.255."&(256-G7),"255.255."&(256-G7/256)&".0") -> 255.255.255.128 | P7: =L7 -> 172.30.6.1
A8: 3 | B8: Gestión de equipos (Management) | C8: 99 | D8: 20 | E8: =CEILING(LOG(D8+2,2),1) -> 5 | F8: ="/"&(32-E8) -> /27 | G8: =2^E8 -> 32 | H8: =G8-2 -> 30 | I8: =H8-D8 -> 10 | J8: =J7+G7 -> 1664 | K8: ="172.30."&INT(J8/256)&"."&MOD(J8,256) -> 172.30.6.128 | L8: ="172.30."&INT((J8+1)/256)&"."&MOD((J8+1),256) -> 172.30.6.129 | M8: ="172.30."&INT((J8+G8-2)/256)&"."&MOD((J8+G8-2),256) -> 172.30.6.158 | N8: ="172.30."&INT((J8+G8-1)/256)&"."&MOD((J8+G8-1),256) -> 172.30.6.159 | O8: =IF(E8<=8,"255.255.255."&(256-G8),"255.255."&(256-G8/256)&".0") -> 255.255.255.224 | P8: =L8 -> 172.30.6.129
B10: Total hosts requeridos | D10: =SUM(D6:D8) -> 320
B11: Total direcciones asignadas | D11: =SUM(G6:G8) -> 416
B12: Eficiencia (hosts req. / direcciones) | D12: =D10/D11 -> 0.76923077
B13: Siguiente dirección libre | D13: ="172.30."&INT((J8+G8)/256)&"."&MOD((J8+G8),256) -> 172.30.6.160
B15: Fórmula: h = mínimo entero tal que 2^h − 2 ≥ hosts requeridos; prefijo = 32 − h. Celdas en azul = datos de entrada del caso.
B16: Wi-Fi Invitados: gateway en R-EDGE Gi0/2 (172.30.5.1), conectado a ASW-ING Fa0/21 desde v6; no hay SVI 60 en DSW1/DSW2.

Sheet FLSM Enlaces
A1: Tabla 3. Plan FLSM /30 para enlaces punto a punto
A2: Bloque 172.30.4.64/27 dividido en 8 subredes de tamaño fijo /30 (2 hosts útiles cada una).
A3: Desplazamiento inicial: | F3: 1088 | G3: Prefijo fijo: | H3: 30
A5: # | B5: Enlace | C5: Extremo A | D5: Extremo B | E5: Desplazamiento | F5: Dirección de red | G5: IP extremo A | H5: IP extremo B | I5: Broadcast | J5: CIDR | K5: Máscara decimal | L5: Hosts útiles
A6: 1 | B6: WAN Sede Central ↔ Norte | C6: R-CORE Se0/0/0 (DCE) | D6: R-NORTE Se0/0/0 | E6: =$F$3 -> 1088 | F6: ="172.30."&INT(E6/256)&"."&MOD(E6,256) -> 172.30.4.64 | G6: ="172.30."&INT((E6+1)/256)&"."&MOD((E6+1),256) -> 172.30.4.65 | H6: ="172.30."&INT((E6+2)/256)&"."&MOD((E6+2),256) -> 172.30.4.66 | I6: ="172.30."&INT((E6+2^(32-$H$3)-1)/256)&"."&MOD((E6+2^(32-$H$3)-1),256) -> 172.30.4.67 | J6: ="/"&$H$3 -> /30 | K6: ="255.255.255."&(256-2^(32-$H$3)) -> 255.255.255.252 | L6: =2^(32-$H$3)-2 -> 2
A7: 2 | B7: WAN Sede Central ↔ Sur | C7: R-CORE Se0/0/1 (DCE) | D7: R-SUR Se0/0/0 | E7: =E6+2^(32-$H$3) -> 1092 | F7: ="172.30."&INT(E7/256)&"."&MOD(E7,256) -> 172.30.4.68 | G7: ="172.30."&INT((E7+1)/256)&"."&MOD((E7+1),256) -> 172.30.4.69 | H7: ="172.30."&INT((E7+2)/256)&"."&MOD((E7+2),256) -> 172.30.4.70 | I7: ="172.30."&INT((E7+2^(32-$H$3)-1)/256)&"."&MOD((E7+2^(32-$H$3)-1),256) -> 172.30.4.71 | J7: ="/"&$H$3 -> /30 | K7: ="255.255.255."&(256-2^(32-$H$3)) -> 255.255.255.252 | L7: =2^(32-$H$3)-2 -> 2
A8: 3 | B8: WAN Sede Central ↔ Occidente | C8: R-CORE Se0/1/0 (DCE) | D8: R-OCCIDENTE Se0/0/0 | E8: =E7+2^(32-$H$3) -> 1096 | F8: ="172.30."&INT(E8/256)&"."&MOD(E8,256) -> 172.30.4.72 | G8: ="172.30."&INT((E8+1)/256)&"."&MOD((E8+1),256) -> 172.30.4.73 | H8: ="172.30."&INT((E8+2)/256)&"."&MOD((E8+2),256) -> 172.30.4.74 | I8: ="172.30."&INT((E8+2^(32-$H$3)-1)/256)&"."&MOD((E8+2^(32-$H$3)-1),256) -> 172.30.4.75 | J8: ="/"&$H$3 -> /30 | K8: ="255.255.255."&(256-2^(32-$H$3)) -> 255.255.255.252 | L8: =2^(32-$H$3)-2 -> 2
A9: 4 | B9: Core ↔ Distribución 1 | C9: R-CORE Gi0/0 | D9: DSW1-SEDE Gi0/1 | E9: =E8+2^(32-$H$3) -> 1100 | F9: ="172.30."&INT(E9/256)&"."&MOD(E9,256) -> 172.30.4.76 | G9: ="172.30."&INT((E9+1)/256)&"."&MOD((E9+1),256) -> 172.30.4.77 | H9: ="172.30."&INT((E9+2)/256)&"."&MOD((E9+2),256) -> 172.30.4.78 | I9: ="172.30."&INT((E9+2^(32-$H$3)-1)/256)&"."&MOD((E9+2^(32-$H$3)-1),256) -> 172.30.4.79 | J9: ="/"&$H$3 -> /30 | K9: ="255.255.255."&(256-2^(32-$H$3)) -> 255.255.255.252 | L9: =2^(32-$H$3)-2 -> 2
A10: 5 | B10: Core ↔ Distribución 2 | C10: R-CORE Gi0/1 | D10: DSW2-SEDE Gi0/1 | E10: =E9+2^(32-$H$3) -> 1104 | F10: ="172.30."&INT(E10/256)&"."&MOD(E10,256) -> 172.30.4.80 | G10: ="172.30."&INT((E10+1)/256)&"."&MOD((E10+1),256) -> 172.30.4.81 | H10: ="172.30."&INT((E10+2)/256)&"."&MOD((E10+2),256) -> 172.30.4.82 | I10: ="172.30."&INT((E10+2^(32-$H$3)-1)/256)&"."&MOD((E10+2^(32-$H$3)-1),256) -> 172.30.4.83 | J10: ="/"&$H$3 -> /30 | K10: ="255.255.255."&(256-2^(32-$H$3)) -> 255.255.255.252 | L10: =2^(32-$H$3)-2 -> 2
A11: 6 | B11: Core ↔ Borde perimetral | C11: R-CORE Gi0/2 | D11: R-EDGE Gi0/0 | E11: =E10+2^(32-$H$3) -> 1108 | F11: ="172.30."&INT(E11/256)&"."&MOD(E11,256) -> 172.30.4.84 | G11: ="172.30."&INT((E11+1)/256)&"."&MOD((E11+1),256) -> 172.30.4.85 | H11: ="172.30."&INT((E11+2)/256)&"."&MOD((E11+2),256) -> 172.30.4.86 | I11: ="172.30."&INT((E11+2^(32-$H$3)-1)/256)&"."&MOD((E11+2^(32-$H$3)-1),256) -> 172.30.4.87 | J11: ="/"&$H$3 -> /30 | K11: ="255.255.255."&(256-2^(32-$H$3)) -> 255.255.255.252 | L11: =2^(32-$H$3)-2 -> 2
A12: 7 | B12: Reserva (crecimiento) | C12: — | D12: — | E12: =E11+2^(32-$H$3) -> 1112 | F12: ="172.30."&INT(E12/256)&"."&MOD(E12,256) -> 172.30.4.88 | G12: ="172.30."&INT((E12+1)/256)&"."&MOD((E12+1),256) -> 172.30.4.89 | H12: ="172.30."&INT((E12+2)/256)&"."&MOD((E12+2),256) -> 172.30.4.90 | I12: ="172.30."&INT((E12+2^(32-$H$3)-1)/256)&"."&MOD((E12+2^(32-$H$3)-1),256) -> 172.30.4.91 | J12: ="/"&$H$3 -> /30 | K12: ="255.255.255."&(256-2^(32-$H$3)) -> 255.255.255.252 | L12: =2^(32-$H$3)-2 -> 2
A13: 8 | B13: Reserva (crecimiento) | C13: — | D13: — | E13: =E12+2^(32-$H$3) -> 1116 | F13: ="172.30."&INT(E13/256)&"."&MOD(E13,256) -> 172.30.4.92 | G13: ="172.30."&INT((E13+1)/256)&"."&MOD((E13+1),256) -> 172.30.4.93 | H13: ="172.30."&INT((E13+2)/256)&"."&MOD((E13+2),256) -> 172.30.4.94 | I13: ="172.30."&INT((E13+2^(32-$H$3)-1)/256)&"."&MOD((E13+2^(32-$H$3)-1),256) -> 172.30.4.95 | J13: ="/"&$H$3 -> /30 | K13: ="255.255.255."&(256-2^(32-$H$3)) -> 255.255.255.252 | L13: =2^(32-$H$3)-2 -> 2
B16: Perímetro (bloque público 200.100.50.0/24): R-EDGE Gi0/1 200.100.50.2/30 ↔ R-ISP Gi0/0 200.100.50.1/30; NAT estático del servidor Web 200.100.50.10.

Sheet CIDR Resumen
A1: Tabla 4. Resumen de rutas (CIDR / supernetting)
A2: Cálculo de la ruta sumarizada que el router de borde usa para alcanzar toda la red interna.
A4: Concepto | B4: Valor | C4: Binario del tercer octeto
A5: Primera red interna | B5: 172.30.0.0 | C5: 00000000
A6: Última dirección usada | B6: 172.30.7.255 | C6: 00000111
A7: Bits comunes del tercer octeto | B7: 5 (00000xxx)
A8: Prefijo resumido | B8: =16+5 -> 21
A9: Ruta resumida | B9: 172.30.0.0/21
A10: Máscara resumida | B10: 255.255.248.0 | C10: 11111000
A11: Rango cubierto | B11: 172.30.0.0 – 172.30.7.255
A12: Direcciones del resumen | B12: =2^(32-B8) -> 2048
A13: Direcciones asignadas por el diseño | B13: ='Resumen y Aprovechamiento'!D9 -> 1536
A14: Espacio libre para crecimiento | B14: =B12-B13 -> 512
A15: Reserva no asignable | B15: 172.30.0.0/24
A16: Motivo: con Ingeniería en 172.30.0.0/24, PT 9 originaba la /24 y la /21 con el mismo Link State ID y R-EDGE no aprendía el resumen de forma consistente.
A17: Aplicación en la versión final: R-CORE (ABR) anuncia «area 0 range 172.30.0.0 255.255.248.0»; R-EDGE aprende solo O IA 172.30.0.0/21, también tras reabrir y sin la estática (ver verificación final).
A18: R-EDGE conserva «ip route 172.30.0.0 255.255.248.0 172.30.4.85 120» como estática flotante de respaldo (AD 120 > OSPF 110); no es necesaria para el funcionamiento.
A19: La ACL 1 de NAT usa la misma wildcard 0.0.7.255. Con el crecimiento a 3 años el resumen pasa a 172.30.0.0/19 (ver hoja Crecimiento 3 años).

Sheet VLANs
A1: Tabla 5. VLANs institucionales de la Sede Central
A2: Gateway = IP virtual HSRP. DSW1 activo en VLAN 10, 30, 50 y 99; DSW2 activo en VLAN 20 y 40. VLAN 60 sin SVI: gateway en R-EDGE Gi0/2 (v5/v6).
A4: VLAN | B4: Nombre | C4: Red | D4: Gateway virtual (HSRP) | E4: SVI DSW1 | F4: SVI DSW2 | G4: Switch de acceso | H4: Router activo HSRP / raíz STP
A5: 10 | B5: INGENIERIA | C5: 172.30.7.0/24 | D5: 172.30.7.1 | E5: 172.30.7.2 | F5: 172.30.7.3 | G5: ASW-ING | H5: DSW1
A6: 20 | B6: ADMINISTRATIVO | C6: 172.30.2.0/25 | D6: 172.30.2.1 | E6: 172.30.2.2 | F6: 172.30.2.3 | G6: ASW-ADM | H6: DSW2
A7: 30 | B7: FINANZAS | C7: 172.30.3.128/25 | D7: 172.30.3.129 | E7: 172.30.3.130 | F7: 172.30.3.131 | G7: ASW-FIN | H7: DSW1
A8: 40 | B8: DATACENTER | C8: 172.30.4.0/26 | D8: 172.30.4.1 | E8: 172.30.4.2 | F8: 172.30.4.3 | G8: ASW-DC | H8: DSW2
A9: 50 | B9: WIFI-CORP | C9: 172.30.6.0/25 | D9: 172.30.6.1 | E9: 172.30.6.2 | F9: 172.30.6.3 | G9: ASW-ADM (AP-CORP) | H9: DSW1
A10: 60 | B10: WIFI-INVITADOS | C10: 172.30.5.0/24 | D10: 172.30.5.1 (R-EDGE Gi0/2) | E10: — | F10: — | G10: ASW-ING (AP-GUEST, R-EDGE en Fa0/21) | H10: R-EDGE (sin HSRP)
A11: 99 | B11: GESTION | C11: 172.30.6.128/27 | D11: 172.30.6.129 | E11: 172.30.6.130 | F11: 172.30.6.131 | G11: Todos | H11: DSW1
A12: 999 | B12: NATIVA (sin uso, seguridad) | C12: — | D12: — | E12: — | F12: — | G12: Troncales 802.1Q | H12: —

Sheet Matriz IP
A1: Tabla 6. Matriz de direccionamiento IP por dispositivo
A2: Direcciones estáticas de infraestructura (versión final: v6 con Ingeniería en 172.30.7.0/24). Los hosts reciben IP por DHCP: SRV-DHCP 172.30.4.11 (≈70 % de cada ámbito) y SRV-DHCP-2 172.30.4.16 (≈30 %).
A4: Dispositivo | B4: Modelo | C4: Interfaz | D4: Dirección IP | E4: Máscara | F4: Gateway / siguiente salto | G4: Descripción
A5: R-ISP | B5: 2911 | C5: Gi0/0 | D5: 200.100.50.1 | E5: 255.255.255.252 | F5: — | G5: Enlace al borde de Nexus
A6: R-ISP | B6: 2911 | C6: Gi0/1 | D6: 8.8.8.1 | E6: 255.255.255.0 | F6: — | G6: Red simulada de Internet
A7: R-EDGE | B7: 2911 | C7: Gi0/0 | D7: 172.30.4.86 | E7: 255.255.255.252 | F7: — | G7: Hacia R-CORE
A8: R-EDGE | B8: 2911 | C8: Gi0/1 | D8: 200.100.50.2 | E8: 255.255.255.252 | F8: 200.100.50.1 | G8: Hacia ISP (NAT outside)
A9: R-CORE | B9: 2911 | C9: Gi0/0 | D9: 172.30.4.77 | E9: 255.255.255.252 | F9: — | G9: Hacia DSW1-SEDE
A10: R-CORE | B10: 2911 | C10: Gi0/1 | D10: 172.30.4.81 | E10: 255.255.255.252 | F10: — | G10: Hacia DSW2-SEDE
A11: R-CORE | B11: 2911 | C11: Gi0/2 | D11: 172.30.4.85 | E11: 255.255.255.252 | F11: — | G11: Hacia R-EDGE
A12: R-CORE | B12: 2911 | C12: Se0/0/0 | D12: 172.30.4.65 | E12: 255.255.255.252 | F12: — | G12: WAN Norte (DCE 64000)
A13: R-CORE | B13: 2911 | C13: Se0/0/1 | D13: 172.30.4.69 | E13: 255.255.255.252 | F13: — | G13: WAN Sur (DCE 64000)
A14: R-CORE | B14: 2911 | C14: Se0/1/0 | D14: 172.30.4.73 | E14: 255.255.255.252 | F14: — | G14: WAN Occidente (DCE 64000)
A15: R-NORTE | B15: 2911 | C15: Se0/0/0 | D15: 172.30.4.66 | E15: 255.255.255.252 | F15: — | G15: WAN a Sede Central
... A39: SRV-DNS-2 | B39: Server-PT | C39: Fa0 | D39: 172.30.4.17 | E39: 255.255.255.192 | F39: 172.30.4.1 | G39: DNS secundario, mismos registros A (ASW-DC Fa0/8)
A41: Dimensionamiento del Data Center (172.30.4.0/26) para 35 servidores
A42: Direcciones útiles | B42: =2^(32-26)-2 -> 62
A43: Gateways (.1–.3) | B43: 3
A44: Servidores requeridos por el enunciado | B44: 35
A45: serverPool de PT (.61, .62) | B45: 2
A46: Ocupadas al llegar a 35 | B46: =SUM(B43:B45) -> 40
A47: Libres | B47: =B42-B46 -> 22
A48: Servidores representados en el .pkt | B48: =COUNTIFS(D5:D39,"172.30.4.*",B5:B39,"Server-PT") -> 8
A49: Los 8 servidores del .pkt (DNS, DHCP, web, FTP/TFTP, correo, BD y los respaldos DHCP/DNS) son una representación funcional de los 35, igual que las PCs representan a los usuarios de cada departamento. Los 27 restantes usarían .18 a .44.

Sheet Línea base
A1: Tabla 9. Línea base: latencia, jitter y throughput
A2: Pegar los 50 tiempos (ms) de cada serie en su columna, en orden; un paquete perdido deja su celda en blanco y se cuenta en la fila Perdidos. El jitter solo usa pares de respuestas consecutivas.
A3: Datos v6: 3 series × 6 destinos × 50 pings desde PC-ING-1/2/3 (entrega2/revision/evidencias_v6/linea_base_muestras.csv). «<1 ms» = 0; los perdidos quedan en blanco.
A4: Serie → | B4: PC-ADM-1 S1 | C4: PC-ADM-1 S2 | D4: PC-ADM-1 S3 | E4: SRV-WEB S1 | F4: SRV-WEB S2 | G4: SRV-WEB S3 | H4: PC-NORTE-1 S1 | I4: PC-NORTE-1 S2 | J4: PC-NORTE-1 S3 | K4: PC-SUR-1 S1 | L4: PC-SUR-1 S2 | M4: PC-SUR-1 S3 | N4: PC-OCC-1 S1 | O4: PC-OCC-1 S2 | P4: PC-OCC-1 S3 | Q4: 8.8.8.8 S1 | R4: 8.8.8.8 S2 | S4: 8.8.8.8 S3
A5: 1 | C5: 0 | D5: 3 | E5: 0 | F5: 0 | G5: 0 | H5: 15 | I5: 1 | J5: 23 | K5: 1 | L5: 2 | M5: 1 | O5: 2 | P5: 2 | Q5: 18 | R5: 10 | S5: 23
A6: 2 | B6: 0 | C6: 0 | D6: 0 | E6: 0 | F6: 0 | G6: 1 | H6: 1 | I6: 1 | J6: 10 | K6: 8 | L6: 1 | M6: 19 | N6: 5 | O6: 17 | P6: 2 | Q6: 0 | R6: 0 | S6: 10
A7: 3 | B7: 0 | C7: 32 | D7: 0 | E7: 0 | F7: 1 | G7: 0 | I7: 1 | J7: 1 | K7: 1 | L7: 20 | M7: 1 | N7: 12 | O7: 4 | P7: 13 | Q7: 0 | R7: 1 | S7: 9
A8: 4 | B8: 0 | C8: 0 | D8: 0 | E8: 0 | F8: 1 | G8: 0 | H8: 15 | I8: 10 | J8: 2 | K8: 8 | L8: 4 | M8: 7 | N8: 1 | O8: 1 | P8: 1 | Q8: 10 | R8: 10 | S8: 0
A9: 5 | B9: 0 | C9: 1 | D9: 0 | E9: 1 | F9: 0 | G9: 0 | H9: 1 | I9: 1 | J9: 1 | K9: 2 | L9: 12 | M9: 11 | N9: 1 | O9: 1 | P9: 1 | Q9: 0 | R9: 10 | S9: 2
A10: 6 | B10: 2 | C10: 0 | D10: 0 | E10: 0 | F10: 0 | G10: 11 | H10: 2 | I10: 1 | J10: 2 | K10: 1 | L10: 11 | M10: 4 | N10: 1 | O10: 2 | P10: 1 | Q10: 0 | R10: 0 | S10: 13
A11: 7 | B11: 1 | C11: 0 | D11: 0 | E11: 0 | F11: 0 | G11: 23 | H11: 1 | I11: 21 | J11: 2 | K11: 1 | L11: 21 | M11: 1 | N11: 10 | O11: 1 | P11: 0 | Q11: 0 | R11: 0 | S11: 36
A12: 8 | B12: 1 | C12: 0 | D12: 9 | E12: 0 | F12: 10 | G12: 1 | H12: 1 | I12: 1 | J12: 3 | K12: 1 | L12: 2 | M12: 2 | N12: 1 | O12: 1 | P12: 1 | Q12: 0 | R12: 0 | S12: 13
A13: 9 | B13: 11 | C13: 0 | D13: 0 | E13: 0 | F13: 0 | G13: 0 | H13: 4 | I13: 1 | J13: 1 | K13: 1 | L13: 1 | M13: 1 | N13: 1 | O13: 1 | P13: 1 | Q13: 0 | R13: 13 | S13: 1
A14: 10 | B14: 1 | C14: 1 | D14: 1 | E14: 0 | F14: 0 | G14: 0 | H14: 1 | I14: 1 | J14: 1 | K14: 2 | L14: 1 | M14: 1 | N14: 1 | O14: 3 | P14: 10 | Q14: 0 | R14: 0 | S14: 10
A15: 11 | B15: 7 | C15: 0 | D15: 0 | E15: 0 | F15: 0 | G15: 0 | H15: 2 | I15: 20 | J15: 1 | K15: 2 | L15: 1 | M15: 1 | N15: 1 | O15: 1 | P15: 2 | Q15: 7 | R15: 0 | S15: 10
A16: 12 | B16: 0 | C16: 0 | D16: 0 | E16: 0 | F16: 2 | G16: 10 | H16: 2 | I16: 11 | J16: 1 | K16: 1 | L16: 1 | M16: 2 | N16: 1 | O16: 2 | P16: 1 | Q16: 1 | R16: 0 | S16: 10
A17: 13 | B17: 0 | C17: 0 | D17: 0 | E17: 0 | F17: 0 | G17: 0 | H17: 17 | I17: 1 | J17: 1 | K17: 1 | L17: 1 | M17: 1 | N17: 2 | O17: 1 | P17: 1 | Q17: 0 | R17: 10 | S17: 10
A18: 14 | B18: 0 | C18: 8 | D18: 1 | E18: 2 | F18: 0 | G18: 10 | H18: 14 | I18: 2 | J18: 1 | K18: 1 | L18: 1 | M18: 1 | N18: 2 | O18: 2 | P18: 1 | Q18: 12 | R18: 0 | S18: 0
A19: 15 | B19: 10 | C19: 16 | D19: 1 | E19: 0 | F19: 0 | G19: 24 | H19: 1 | I19: 1 | J19: 1 | K19: 10 | L19: 1 | M19: 1 | N19: 1 | O19: 10 | P19: 16 | Q19: 0 | R19: 0 | S19: 10
... A54: 50 | B54: 1 | C54: 13 | D54: 0 | E54: 0 | F54: 10 | G54: 0 | H54: 1 | I54: 1 | J54: 1 | K54: 1 | L54: 1 | M54: 25 | N54: 1 | O54: 1 | P54: 2 | Q54: 0 | R54: 0 | S54: 6
A55: Recibidos | B55: =COUNT(B5:B54) -> 49 | C55: =COUNT(C5:C54) -> 50 | D55: =COUNT(D5:D54) -> 50 | E55: =COUNT(E5:E54) -> 50 | F55: =COUNT(F5:F54) -> 50 | G55: =COUNT(G5:G54) -> 50 | H55: =COUNT(H5:H54) -> 49 | I55: =COUNT(I5:I54) -> 50 | ... S55: =COUNT(S5:S54) -> 50
A56: Perdidos | B56: 1 | C56: 0 | D56: 0 | E56: 0 | F56: 0 | G56: 0 | H56: 1 | I56: 0 | J56: 0 | K56: 0 | L56: 0 | M56: 0 | N56: 1 | O56: 0 | P56: 0 | Q56: 0 | R56: 0 | S56: 0
A57: Pérdida (%) | B57: =IF(B55+B56=0,"",B56/(B55+B56)) -> 0.02 | C57: =IF(C55+C56=0,"",C56/(C55+C56)) -> 0 | D57: =IF(D55+D56=0,"",D56/(D55+D56)) -> 0 | E57: =IF(E55+E56=0,"",E56/(E55+E56)) -> 0 | F57: =IF(F55+F56=0,"",F56/(F55+F56)) -> 0 | G57: =IF(G55+G56=0,"",G56/(G55+G56)) -> 0 | H57: =IF(H55+H56=0,"",H56/(H55+H56)) -> 0.02 | I57: =IF(I55+I56=0,"",I56/(I55+I56)) -> 0 | ... S57: =IF(S55+S56=0,"",S56/(S55+S56)) -> 0
A58: Mínimo (ms) | B58: =IF(B55=0,"",MIN(B5:B54)) -> 0 | C58: =IF(C55=0,"",MIN(C5:C54)) -> 0 | D58: =IF(D55=0,"",MIN(D5:D54)) -> 0 | E58: =IF(E55=0,"",MIN(E5:E54)) -> 0 | F58: =IF(F55=0,"",MIN(F5:F54)) -> 0 | G58: =IF(G55=0,"",MIN(G5:G54)) -> 0 | H58: =IF(H55=0,"",MIN(H5:H54)) -> 1 | I58: =IF(I55=0,"",MIN(I5:I54)) -> 1 | ... S58: =IF(S55=0,"",MIN(S5:S54)) -> 0
A59: Promedio (ms) | B59: =IF(B55=0,"",AVERAGE(B5:B54)) -> 2.1836735 | C59: =IF(C55=0,"",AVERAGE(C5:C54)) -> 2.44 | D59: =IF(D55=0,"",AVERAGE(D5:D54)) -> 1.12 | E59: =IF(E55=0,"",AVERAGE(E5:E54)) -> 1.02 | F59: =IF(F55=0,"",AVERAGE(F5:F54)) -> 1.6 | G59: =IF(G55=0,"",AVERAGE(G5:G54)) -> 4.06 | H59: =IF(H55=0,"",AVERAGE(H5:H54)) -> 4.4897959 | I59: =IF(I55=0,"",AVERAGE(I5:I54)) -> 7.18 | ... S59: =IF(S55=0,"",AVERAGE(S5:S54)) -> 4.26
A60: Máximo (ms) | B60: =IF(B55=0,"",MAX(B5:B54)) -> 27 | C60: =IF(C55=0,"",MAX(C5:C54)) -> 32 | D60: =IF(D55=0,"",MAX(D5:D54)) -> 11 | E60: =IF(E55=0,"",MAX(E5:E54)) -> 10 | F60: =IF(F55=0,"",MAX(F5:F54)) -> 15 | G60: =IF(G55=0,"",MAX(G5:G54)) -> 24 | H60: =IF(H55=0,"",MAX(H5:H54)) -> 30 | I60: =IF(I55=0,"",MAX(I5:I54)) -> 107 | ... S60: =IF(S55=0,"",MAX(S5:S54)) -> 36
A61: Jitter (ms) = media |t(i) − t(i−1)| | B61: =IF(SUMPRODUCT((B6:B54<>"")*(B5:B53<>""))=0,"",SUMPRODUCT((B6:B54<>"")*(B5:B53<>"")*ABS(B6:B54-B5:B53))/SUMPRODUCT((B6:B54<>"")*(B5:B53<>""))) -> 3.6041667 | C61: =IF(SUMPRODUCT((C6:C54<>"")*(C5:C53<>""))=0,"",SUMPRODUCT((C6:C54<>"")*(C5:C53<>"")*ABS(C6:C54-C5:C53))/SUMPRODUCT((C6:C54<>"")*(C5:C53<>""))) -> 3.5306122 | D61: =IF(SUMPRODUCT((D6:D54<>"")*(D5:D53<>""))=0,"",SUMPRODUCT((D6:D54<>"")*(D5:D53<>"")*ABS(D6:D54-D5:D53))/SUMPRODUCT((D6:D54<>"")*(D5:D53<>""))) -> 1.8979592 | E61: =IF(SUMPRODUCT((E6:E54<>"")*(E5:E53<>""))=0,"",SUMPRODUCT((E6:E54<>"")*(E5:E53<>"")*ABS(E6:E54-E5:E53))/SUMPRODUCT((E6:E54<>"")*(E5:E53<>""))) -> 1.9591837 | F61: =IF(SUMPRODUCT((F6:F54<>"")*(F5:F53<>""))=0,"",SUMPRODUCT((F6:F54<>"")*(F5:F53<>"")*ABS(F6:F54-F5:F53))/SUMPRODUCT((F6:F54<>"")*(F5:F53<>""))) -> 2.2040816 | G61: =IF(SUMPRODUCT((G6:G54<>"")*(G5:G53<>""))=0,"",SUMPRODUCT((G6:G54<>"")*(G5:G53<>"")*ABS(G6:G54-G5:G53))/SUMPRODUCT((G6:G54<>"")*(G5:G53<>""))) -> 4.8979592 | H61: =IF(SUMPRODUCT((H6:H54<>"")*(H5:H53<>""))=0,"",SUMPRODUCT((H6:H54<>"")*(H5:H53<>"")*ABS(H6:H54-H5:H53))/SUMPRODUCT((H6:H54<>"")*(H5:H53<>""))) -> 3.787234 | I61: =IF(SUMPRODUCT((I6:I54<>"")*(I5:I53<>""))=0,"",SUMPRODUCT((I6:I54<>"")*(I5:I53<>"")*ABS(I6:I54-I5:I53))/SUMPRODUCT((I6:I54<>"")*(I5:I53<>""))) -> 10.612245 | ... S61: =IF(SUMPRODUCT((S6:S54<>"")*(S5:S53<>""))=0,"",SUMPRODUCT((S6:S54<>"")*(S5:S53<>"")*ABS(S6:S54-S5:S53))/SUMPRODUCT((S6:S54<>"")*(S5:S53<>""))) -> 4.8367347
A63: Resumen por destino (promedio de las 3 series)
A64: Destino | B64: Latencia mín. (ms) | C64: Latencia prom. (ms) | D64: Latencia máx. (ms) | E64: Jitter prom. (ms) | F64: Pérdida (%)
A65: PC-ADM-1 | B65: =IF(SUM(B55:D55)=0,"",IFERROR(MIN(B58:D58),"")) -> 0 | C65: =IF(SUM(B55:D55)=0,"",IFERROR(AVERAGE(B59:D59),"")) -> 1.9145578 | D65: =IF(SUM(B55:D55)=0,"",IFERROR(MAX(B60:D60),"")) -> 32 | E65: =IF(SUM(B55:D55)=0,"",IFERROR(AVERAGE(B61:D61),"")) -> 3.0109127 | F65: =IF(SUM(B55:D55)=0,"",IFERROR(SUM(B56:D56)/(SUM(B55:D55)+SUM(B56:D56)),"")) -> 0.0066666667
A66: SRV-WEB | B66: =IF(SUM(E55:G55)=0,"",IFERROR(MIN(E58:G58),"")) -> 0 | C66: =IF(SUM(E55:G55)=0,"",IFERROR(AVERAGE(E59:G59),"")) -> 2.2266667 | D66: =IF(SUM(E55:G55)=0,"",IFERROR(MAX(E60:G60),"")) -> 24 | E66: =IF(SUM(E55:G55)=0,"",IFERROR(AVERAGE(E61:G61),"")) -> 3.0204082 | F66: =IF(SUM(E55:G55)=0,"",IFERROR(SUM(E56:G56)/(SUM(E55:G55)+SUM(E56:G56)),"")) -> 0
A67: PC-NORTE-1 | B67: =IF(SUM(H55:J55)=0,"",IFERROR(MIN(H58:J58),"")) -> 1 | C67: =IF(SUM(H55:J55)=0,"",IFERROR(AVERAGE(H59:J59),"")) -> 4.7365986 | D67: =IF(SUM(H55:J55)=0,"",IFERROR(MAX(H60:J60),"")) -> 107 | E67: =IF(SUM(H55:J55)=0,"",IFERROR(AVERAGE(H61:J61),"")) -> 5.5209147 | F67: =IF(SUM(H55:J55)=0,"",IFERROR(SUM(H56:J56)/(SUM(H55:J55)+SUM(H56:J56)),"")) -> 0.0066666667
A68: PC-SUR-1 | B68: =IF(SUM(K55:M55)=0,"",IFERROR(MIN(K58:M58),"")) -> 0 | C68: =IF(SUM(K55:M55)=0,"",IFERROR(AVERAGE(K59:M59),"")) -> 3.3133333 | D68: =IF(SUM(K55:M55)=0,"",IFERROR(MAX(K60:M60),"")) -> 27 | E68: =IF(SUM(K55:M55)=0,"",IFERROR(AVERAGE(K61:M61),"")) -> 3.7210884 | F68: =IF(SUM(K55:M55)=0,"",IFERROR(SUM(K56:M56)/(SUM(K55:M55)+SUM(K56:M56)),"")) -> 0
A69: PC-OCC-1 | B69: =IF(SUM(N55:P55)=0,"",IFERROR(MIN(N58:P58),"")) -> 0 | C69: =IF(SUM(N55:P55)=0,"",IFERROR(AVERAGE(N59:P59),"")) -> 3.0130612 | D69: =IF(SUM(N55:P55)=0,"",IFERROR(MAX(N60:P60),"")) -> 26 | E69: =IF(SUM(N55:P55)=0,"",IFERROR(AVERAGE(N61:P61),"")) -> 3.731576 | F69: =IF(SUM(N55:P55)=0,"",IFERROR(SUM(N56:P56)/(SUM(N55:P55)+SUM(N56:P56)),"")) -> 0.0066666667
A70: 8.8.8.8 | B70: =IF(SUM(Q55:S55)=0,"",IFERROR(MIN(Q58:S58),"")) -> 0 | C70: =IF(SUM(Q55:S55)=0,"",IFERROR(AVERAGE(Q59:S59),"")) -> 3.2866667 | D70: =IF(SUM(Q55:S55)=0,"",IFERROR(MAX(Q60:S60),"")) -> 36 | E70: =IF(SUM(Q55:S55)=0,"",IFERROR(AVERAGE(Q61:S61),"")) -> 5.0136054 | F70: =IF(SUM(Q55:S55)=0,"",IFERROR(SUM(Q56:S56)/(SUM(Q55:S55)+SUM(Q56:S56)),"")) -> 0
A72: Ejemplo de jitter
A73: Tiempos (ms) | B73: 2 | C73: 10 | D73: 4 | E73: 12 | F73: 3
A74: Jitter (ms) | B74: =SUMPRODUCT(ABS(C73:F73-B73:E73))/(COUNT(B73:F73)-1) -> 7.75 | C74: (|10−2| + |4−10| + |12−4| + |3−12|) ÷ 4 = 31 ÷ 4 = 7.75 ms. El método anterior, (máx − mín) ÷ 2, daría 5 ms y no mide la variación entre paquetes consecutivos.
A77: Throughput FTP
A78: Transferencia | B78: Tamaño (bytes) | C78: Tiempo (s) | D78: Throughput (kbps) | E78: Fórmula
...
